Workbook

Sheet Summary
A1: Price (€/MWh) | B1: 80
A2: Outage: Lost energy during the outage (1–3 Sep)
A3: Number | B3: T1 | C3: T2 | D3: T3 | E3: Total
A4: Lost energy (kWh) | B4: =SUM('2 Outage'!M4:M435) -> 86156.833 | C4: =SUM('2 Outage'!Q4:Q435) -> 107604.5 | D4: =SUM('2 Outage'!U4:U435) -> 85382.667 | E4: =SUM(B4:D4) -> 279144 | F4: Sum of all 432 ten-minute slots. kWh = energy actually produced (power × time).
A5: Lost energy (MWh) | B5: =B4/1000 -> 86.156833 | C5: =C4/1000 -> 107.6045 | D5: =D4/1000 -> 85.382667 | E5: =E4/1000 -> 279.144 | F5: 1 MWh = 1,000 kWh.
A6: Lost revenue (€) | B6: =B5*$B$1 -> 6892.5467 | C6: =C5*$B$1 -> 8608.36 | D6: =D5*$B$1 -> 6830.6133 | E6: =E5*$B$1 -> 22331.52 | F6: MWh x price. BayWa is paid per MWh delivered.
A7: Average predicted wind (m/s) | B7: =AVERAGE('2 Outage'!J4:J435) -> 6.0627307 | C7: =AVERAGE('2 Outage'!N4:N435) -> 6.4741935 | D7: =AVERAGE('2 Outage'!R4:R435) -> 6.03198 | F7: Mostly 4–9 m/s: the steep part of the power curve, where wind errors matter most. | L7: Wind park T · outage 01.09.2026 00:00 – 03.09.2026 23:50 (72 h) · references H1–H5, O1, O2 · simple method: wind speed only, one straight line per turbine. Every number is an Excel formula — click it to see where it comes from.
A9: From July + August
A10: Number | B10: T1 | C10: T2 | D10: T3 | E10: Total
A11: Slope | B11: ='1 Relationship'!$O$3 -> 0.73031967 | C11: ='1 Relationship'!$P$3 -> 0.84219511 | D11: ='1 Relationship'!$Q$3 -> 0.74592579 | F11: Like a beta: +1 m/s at the neighbours → this many m/s more at the turbine. <1 = turbine is a bit more sheltered.
A12: Intercept (m/s) | B12: ='1 Relationship'!$O$4 -> 0.95577117 | C12: ='1 Relationship'!$P$4 -> 0.58491446 | D12: ='1 Relationship'!$Q$4 -> 0.81589035 | F12: Base amount (like a taxi base fee). Rule: T wind = intercept + slope × neighbours.
A13: R² (0–1) | B13: ='1 Relationship'!$O$5 -> 0.54092528 | C13: ='1 Relationship'!$P$5 -> 0.65267097 | D13: ='1 Relationship'!$Q$5 -> 0.61441146 | F13: Share of the ups and downs the neighbours explain. The rest = local gusts no neighbour can see.
A14: Correlation (0–1) | B14: ='1 Relationship'!$O$6 -> 0.73547622 | C14: ='1 Relationship'!$P$6 -> 0.80788054 | D14: ='1 Relationship'!$Q$6 -> 0.78384403 | F14: How closely they move together. T1 is lowest → hardest to predict.
A15: Rows used | B15: ='1 Relationship'!$O$7 -> 7622 | C15: ='1 Relationship'!$P$7 -> 7622 | D15: ='1 Relationship'!$Q$7 -> 7622 | F15: Number of 10-minute values the rule was learned from (≈ 54 days).
A17: Check: 4–9 Sep (which are the real values known)
A18: Number | B18: T1 | C18: T2 | D18: T3 | E18: Total
A19: Wind RMSE (m/s) | B19: =SQRT(SUMSQ('3 Check'!O3:O866)/COUNT('3 Check'!O3:O866)) -> 1.5598699 | C19: =SQRT(SUMSQ('3 Check'!AA3:AA866)/COUNT('3 Check'!AA3:AA866)) -> 1.2540058 | D19: =SQRT(SUMSQ('3 Check'!AM3:AM866)/COUNT('3 Check'!AM3:AM866)) -> 1.3675659 | F19: Average miss per 10 min, big misses count extra (squared) — like a standard deviation.
A20: Wind MAE (m/s) | B20: =AVERAGE('3 Check'!P3:P866) -> 1.2551914 | C20: =AVERAGE('3 Check'!AB3:AB866) -> 0.97257767 | D20: =AVERAGE('3 Check'!AN3:AN866) -> 1.0664869 | F20: Plain average miss per 10 min, ignoring + / −.
A21: Wind bias (m/s) | B21: =AVERAGE('3 Check'!O3:O866) -> 0.36645816 | C21: =AVERAGE('3 Check'!AA3:AA866) -> -0.26819212 | D21: =AVERAGE('3 Check'!AM3:AM866) -> -0.33077338 | F21: Average error WITH sign. Positive = systematically too high, negative = too low.
A22: Power RMSE (kW) | B22: =SQRT(SUMSQ('3 Check'!R3:R866)/COUNT('3 Check'!R3:R866)) -> 925.15143 | C22: =SQRT(SUMSQ('3 Check'!AD3:AD866)/COUNT('3 Check'!AD3:AD866)) -> 807.6735 | D22: =SQRT(SUMSQ('3 Check'!AP3:AP866)/COUNT('3 Check'!AP3:AP866)) -> 908.3798 | F22: Same as wind RMSE, but after converting to power.
A23: Power MAE (kW) | B23: =AVERAGE('3 Check'!S3:S866) -> 680.28125 | C23: =AVERAGE('3 Check'!AE3:AE866) -> 552.68634 | D23: =AVERAGE('3 Check'!AQ3:AQ866) -> 642.19097 | F23: Plain average power miss per 10 min.
A24: Measured energy (MWh) | B24: =SUM('3 Check'!T3:T866)/1000 -> 213.032 | C24: =SUM('3 Check'!AF3:AF866)/1000 -> 311.42867 | D24: =SUM('3 Check'!AR3:AR866)/1000 -> 272.23167 | E24: =SUM(B24:D24) -> 796.69233 | F24: What the turbines really would have produced on these days.
A25: Predicted energy (MWh) | B25: =SUM('3 Check'!U3:U866)/1000 -> 234.9995 | C25: =SUM('3 Check'!AG3:AG866)/1000 -> 281.2325 | D25: =SUM('3 Check'!AS3:AS866)/1000 -> 233.5885 | E25: =SUM(B25:D25) -> 749.8205 | F25: What our rule says, same 10-min slots.
A26: Energy deviation | B26: =B25/B24-1 -> 0.10311831 | C26: =C25/C24-1 -> -0.096960139 | D26: =D25/D24-1 -> -0.14194957 | E26: =E25/E24-1 -> -0.058833042 | F26: THE key accuracy number for a claim: is the total right? Random errors cancel out over many slots, a bias does not.

Sheet Power curve
A1: Wind speed (m/s) | B1: T1 power (kW) | C1: T2 power (kW) | D1: T3 power (kW)
A2: 0.5 | B2: 0 | C2: 0 | D2: 0
A3: 1 | B3: 0 | C3: 0 | D3: 0
A4: 1.5 | B4: 0 | C4: 0 | D4: 0
A5: 2 | B5: 0 | C5: 0 | D5: 0
A6: 2.5 | B6: 0 | C6: 0 | D6: 0
A7: 3 | B7: 31 | C7: 31 | D7: 31
A8: 3.5 | B8: 122 | C8: 122 | D8: 122
A9: 4 | B9: 247 | C9: 247 | D9: 247
A10: 4.5 | B10: 400 | C10: 400 | D10: 400
A11: 5 | B11: 584 | C11: 584 | D11: 584
A12: 5.5 | B12: 800 | C12: 800 | D12: 800
A13: 6 | B13: 1054 | C13: 1054 | D13: 1054
... A53: 26 | B53: 2529 | C53: 2529 | D53: 2529

Sheet 1 Relationship
A1: Relationship
N2: Number | O2: T1 | P2: T2 | Q2: T3 | R2: What it means
N3: Slope | O3: =SLOPE(J8:J7629,I8:I7629) -> 0.73031967 | P3: =SLOPE(K8:K7629,I8:I7629) -> 0.84219511 | Q3: =SLOPE(L8:L7629,I8:I7629) -> 0.74592579 | R3: Like a beta: +1 m/s at the neighbours → this many m/s more at the turbine.
N4: Intercept (m/s) | O4: =INTERCEPT(J8:J7629,I8:I7629) -> 0.95577117 | P4: =INTERCEPT(K8:K7629,I8:I7629) -> 0.58491446 | Q4: =INTERCEPT(L8:L7629,I8:I7629) -> 0.81589035 | R4: The base amount, like a taxi base fee. = average T − slope × average neighbours.
N5: R² (0–1) | O5: =RSQ(J8:J7629,I8:I7629) -> 0.54092528 | P5: =RSQ(K8:K7629,I8:I7629) -> 0.65267097 | Q5: =RSQ(L8:L7629,I8:I7629) -> 0.61441146 | R5: Share of the turbine's ups and downs explained by the neighbours (like R² of a stock vs the DAX).
N6: Correlation (0–1) | O6: =CORREL(J8:J7629,I8:I7629) -> 0.73547622 | P6: =CORREL(K8:K7629,I8:I7629) -> 0.80788054 | Q6: =CORREL(L8:L7629,I8:I7629) -> 0.78384403 | R6: How closely the two move together. 1 = perfectly in step.
A7: Timestamp | B7: H1 | C7: H2 | D7: H3 | E7: H4 | F7: H5 | G7: O1 | H7: O2 | I7: Neighbours average (m/s) | J7: T1 measured (m/s) | K7: T2 measured (m/s) | L7: T3 measured (m/s) | N7: Rows used | O7: =COUNT(J8:J7629) -> 7622 | P7: =COUNT(K8:K7629) -> 7622 | Q7: =COUNT(L8:L7629) -> 7622 | R7: 10-minute values used to learn the rule (more = more evidence).
A8: 46204 | B8: 5.631 | C8: 6.254 | D8: 6.771 | E8: 6.717 | F8: 5.684 | G8: 2.5 | H8: 1.7 | I8: =AVERAGE(B8:H8) -> 5.0367143 | J8: 4.865 | K8: 4.756 | L8: 4.83
A9: 46204.014 | B9: 4.966 | C9: 5.159 | D9: 5.114 | E9: 5.484 | F9: 5.441 | G9: 3.5 | H9: 2.6 | I9: =AVERAGE(B9:H9) -> 4.6091429 | J9: 2.952 | K9: 2.612 | L9: 2.448
A10: 46204.021 | B10: 4.984 | C10: 5.016 | D10: 5.289 | E10: 5.269 | F10: 6.257 | G10: 3.3 | H10: 3 | I10: =AVERAGE(B10:H10) -> 4.7307143 | J10: 1.353 | K10: 1.57 | L10: 1.628
A11: 46204.028 | B11: 5.017 | C11: 5.426 | D11: 5.239 | E11: 4.429 | F11: 6.132 | G11: 3.4 | H11: 2.6 | I11: =AVERAGE(B11:H11) -> 4.6061429 | J11: 1.354 | K11: 1.345 | L11: 0.92
A12: 46204.035 | B12: 5.2 | C12: 5.067 | D12: 5.17 | E12: 4.542 | F12: 6.129 | G12: 2.2 | H12: 1.8 | I12: =AVERAGE(B12:H12) -> 4.3011429 | J12: 1.569 | K12: 1.552 | L12: 0.888
A13: 46204.042 | B13: 3.699 | C13: 3.764 | D13: 4.018 | E13: 4.092 | F13: 4.372 | G13: 1.3 | H13: 0.7 | I13: =AVERAGE(B13:H13) -> 3.135 | J13: 0.741 | K13: 0.721 | L13: 0.951
A14: 46204.049 | B14: 4.042 | C14: 3.778 | D14: 3.984 | E14: 3.765 | F14: 4.478 | G14: 0.4 | H14: 0.1 | I14: =AVERAGE(B14:H14) -> 2.9352857 | J14: 0.707 | K14: 1.047 | L14: 0.554
A15: 46204.062 | B15: 2.75 | C15: 3.812 | D15: 3.79 | E15: 3.586 | F15: 2.876 | G15: 0.1 | H15: 0.3 | I15: =AVERAGE(B15:H15) -> 2.4591429 | J15: 1.059 | K15: 1.585 | L15: 0.939
A16: 46204.069 | B16: 4.163 | C16: 4.3 | D16: 4.681 | E16: 4.563 | F16: 4.548 | G16: 0.5 | H16: 0.4 | I16: =AVERAGE(B16:H16) -> 3.3078571 | J16: 1.183 | K16: 1.195 | L16: 0.787
A17: 46204.076 | B17: 4.48 | C17: 4.213 | D17: 3.846 | E17: 3.688 | F17: 4.696 | G17: 0.5 | H17: 0.4 | I17: =AVERAGE(B17:H17) -> 3.1175714 | J17: 1.816 | K17: 1.223 | L17: 1.2
A18: 46204.083 | B18: 3.073 | C18: 2.411 | D18: 2.7 | E18: 2.179 | F18: 3.173 | G18: 0.9 | H18: 1.1 | I18: =AVERAGE(B18:H18) -> 2.2194286 | J18: 2.24 | K18: 1.866 | L18: 2.073
A19: 46204.09 | B19: 3.016 | C19: 2.697 | D19: 2.74 | E19: 2.878 | F19: 3.64 | G19: 2 | H19: 2.1 | I19: =AVERAGE(B19:H19) -> 2.7244286 | J19: 2.038 | K19: 2.064 | L19: 1.912
... A27: 46204.153 | B27: 2.576 | C27: 2.608 | D27: 2.847 | E27: 2.453 | F27: 2.685 | G27: 1.2 | H27: 1.3 | I27: =AVERAGE(B27:H27) -> 2.2384286 | J27: 2.435 | K27: 2.395 | L27: 2.599
A28: 46204.16 | B28: 3.678 | C28: 3.649 | D28: 3.457 | E28: 3.373 | F28: 3.365 | G28: 2.1 | H28: 1.7 | I28: =AVERAGE(B28:H28) -> 3.046 | J28: 2.597 | K28: 2.317 | L28: 2.914 | N28: (July + August, before the outage)
A29: 46204.167 | B29: 3.042 | C29: 3.479 | D29: 3.412 | E29: 2.903 | F29: 3.278 | G29: 2.4 | H29: 2.1 | I29: =AVERAGE(B29:H29) -> 2.9448571 | J29: 3.16 | K29: 2.804 | L29: 3.095
A30: 46204.174 | B30: 3.284 | C30: 3.325 | D30: 3.311 | E30: 2.782 | F30: 3.452 | G30: 2.4 | H30: 2.5 | I30: =AVERAGE(B30:H30) -> 3.0077143 | J30: 3.338 | K30: 2.857 | L30: 3.558
A31: 46204.181 | B31: 2.958 | C31: 2.992 | D31: 3.019 | E31: 3.179 | F31: 2.886 | G31: 2.1 | H31: 1.6 | I31: =AVERAGE(B31:H31) -> 2.6762857 | J31: 2.872 | K31: 2.591 | L31: 3.025
A32: 46204.194 | B32: 2.128 | C32: 1.916 | D32: 1.424 | E32: 1.884 | F32: 1.737 | G32: 0.6 | H32: 0.2 | I32: =AVERAGE(B32:H32) -> 1.4127143 | J32: 3.62 | K32: 2.904 | L32: 3.289
A33: 46204.201 | B33: 3.014 | C33: 2.84 | D33: 2.83 | E33: 2.78 | F33: 2.847 | G33: 0.9 | H33: 0.7 | I33: =AVERAGE(B33:H33) -> 2.273 | J33: 2.447 | K33: 1.693 | L33: 2.12
A34: 46204.208 | B34: 2.059 | C34: 1.561 | D34: 1.087 | E34: 1.323 | F34: 1.505 | G34: 1 | H34: 1 | I34: =AVERAGE(B34:H34) -> 1.3621429 | J34: 2.289 | K34: 2.418 | L34: 2.652
A35: 46204.215 | B35: 0.877 | C35: 0.53 | D35: 0.956 | E35: 0.508 | F35: 1.314 | G35: 1.2 | H35: 0.9 | I35: =AVERAGE(B35:H35) -> 0.89785714 | J35: 3.024 | K35: 3.572 | L35: 2.383
A36: 46204.222 | B36: 1.544 | C36: 1.306 | D36: 1.258 | E36: 1.372 | F36: 1.621 | G36: 1 | H36: 1.1 | I36: =AVERAGE(B36:H36) -> 1.3144286 | J36: 2.448 | K36: 2.577 | L36: 2.062
A37: 46204.229 | B37: 3.014 | C37: 2.806 | D37: 3.072 | E37: 3.291 | F37: 2.649 | G37: 2 | H37: 1.7 | I37: =AVERAGE(B37:H37) -> 2.6474286 | J37: 2.701 | K37: 3.446 | L37: 2.662
A38: 46204.243 | B38: 3.213 | C38: 3.755 | D38: 3.989 | E38: 4.016 | F38: 3.341 | G38: 2.1 | H38: 2.1 | I38: =AVERAGE(B38:H38) -> 3.2162857 | J38: 2.935 | K38: 4.378 | L38: 2.295
A39: 46204.25 | B39: 4.297 | C39: 4.562 | D39: 4.106 | E39: 4.41 | F39: 4.45 | G39: 2.5 | H39: 2.3 | I39: =AVERAGE(B39:H39) -> 3.8035714 | J39: 3.072 | K39: 3.913 | L39: 3.007
A40: 46204.257 | B40: 3.854 | C40: 3.391 | D40: 3.799 | E40: 3.959 | F40: 3.237 | G40: 2.8 | H40: 2.4 | I40: =AVERAGE(B40:H40) -> 3.3485714 | J40: 3.019 | K40: 3.71 | L40: 2.74
... A7629: 46265.986 | B7629: 9.478 | C7629: 10.2 | D7629: 10.418 | E7629: 10.769 | F7629: 10.436 | G7629: 10.5 | H7629: 11.9 | I7629: =AVERAGE(B7629:H7629) -> 10.528714 | J7629: 7.878 | K7629: 8.261 | L7629: 8.13

Sheet 2 Outage
J1: T1 | N1: T2 | R1: T3
A2: Timestamp | B2: H1 | C2: H2 | D2: H3 | E2: H4 | F2: H5 | G2: O1 | H2: O2 | I2: Neighbours average (m/s) | J2: Predicted wind (m/s) | K2: Rounded to 0.5 | L2: Predicted power (kW) | M2: Predicted energy (kWh) | N2: Predicted wind (m/s) | O2: Rounded to 0.5 | P2: Predicted power (kW) | Q2: Predicted energy (kWh) | R2: Predicted wind (m/s) | S2: Rounded to 0.5 | T2: Predicted power (kW) | U2: Predicted energy (kWh)
A3: every 10 min | B3: Neighbouring turbines, m/s | I3: Formula: AVERAGE of the 7 | J3: Formula: intercept + slope × neighbours (rule from tab 1) | K3: Power curve has 0.5 m/s steps, so we round to look it up | L3: VLOOKUP in the power curve | M3: kW × 10/60 h: energy in this 10-min slot (like km/h × hours = km) | N3: Formula: intercept + slope × neighbours (rule from tab 1) | O3: Power curve has 0.5 m/s steps, so we round to look it up | P3: VLOOKUP in the power curve | Q3: kW × 10/60 h: energy in this 10-min slot (like km/h × hours = km) | R3: Formula: intercept + slope × neighbours (rule from tab 1) | S3: Power curve has 0.5 m/s steps, so we round to look it up | T3: VLOOKUP in the power curve | U3: kW × 10/60 h: energy in this 10-min slot (like km/h × hours = km)
A4: 46266 | B4: 8.732 | C4: 9.271 | D4: 8.746 | E4: 8.131 | F4: 9.569 | G4: 11.2 | H4: 11.9 | I4: =AVERAGE(B4:H4) -> 9.6498571 | J4: =MAX(0,'1 Relationship'!$O$4+'1 Relationship'!$O$3*I4) -> 8.0032516 | K4: =ROUND(J4*2,0)/2 -> 8 | L4: =IFERROR(VLOOKUP(K4,'Power curve'!$A$2:$B$53,2,FALSE()),0) -> 2527 | M4: =L4*10/60 -> 421.16667 | N4: =MAX(0,'1 Relationship'!$P$4+'1 Relationship'!$P$3*I4) -> 8.711977 | O4: =ROUND(N4*2,0)/2 -> 8.5 | P4: =IFERROR(VLOOKUP(O4,'Power curve'!$A$2:$C$53,3,FALSE()),0) -> 3016 | Q4: =P4*10/60 -> 502.66667 | R4: =MAX(0,'1 Relationship'!$Q$4+'1 Relationship'!$Q$3*I4) -> 8.0139677 | S4: =ROUND(R4*2,0)/2 -> 8 | T4: =IFERROR(VLOOKUP(S4,'Power curve'!$A$2:$D$53,4,FALSE()),0) -> 2527 | U4: =T4*10/60 -> 421.16667
A5: 46266.007 | B5: 8.857 | C5: 9.251 | D5: 9.092 | E5: 8.99 | F5: 9.057 | G5: 11.3 | H5: 11.4 | I5: =AVERAGE(B5:H5) -> 9.7067143 | J5: =MAX(0,'1 Relationship'!$O$4+'1 Relationship'!$O$3*I5) -> 8.0447755 | K5: =ROUND(J5*2,0)/2 -> 8 | L5: =IFERROR(VLOOKUP(K5,'Power curve'!$A$2:$B$53,2,FALSE()),0) -> 2527 | M5: =L5*10/60 -> 421.16667 | N5: =MAX(0,'1 Relationship'!$P$4+'1 Relationship'!$P$3*I5) -> 8.7598618 | O5: =ROUND(N5*2,0)/2 -> 9 | P5: =IFERROR(VLOOKUP(O5,'Power curve'!$A$2:$C$53,3,FALSE()),0) -> 3506 | Q5: =P5*10/60 -> 584.33333 | R5: =MAX(0,'1 Relationship'!$Q$4+'1 Relationship'!$Q$3*I5) -> 8.0563789 | S5: =ROUND(R5*2,0)/2 -> 8 | T5: =IFERROR(VLOOKUP(S5,'Power curve'!$A$2:$D$53,4,FALSE()),0) -> 2527 | U5: =T5*10/60 -> 421.16667
A6: 46266.014 | B6: 9.529 | C6: 8.587 | D6: 9.436 | E6: 9.589 | F6: 9.413 | G6: 11.1 | H6: 11.5 | I6: =AVERAGE(B6:H6) -> 9.8791429 | J6: =MAX(0,'1 Relationship'!$O$4+'1 Relationship'!$O$3*I6) -> 8.1707035 | K6: =ROUND(J6*2,0)/2 -> 8 | L6: =IFERROR(VLOOKUP(K6,'Power curve'!$A$2:$B$53,2,FALSE()),0) -> 2527 | M6: =L6*10/60 -> 421.16667 | N6: =MAX(0,'1 Relationship'!$P$4+'1 Relationship'!$P$3*I6) -> 8.9050803 | O6: =ROUND(N6*2,0)/2 -> 9 | P6: =IFERROR(VLOOKUP(O6,'Power curve'!$A$2:$C$53,3,FALSE()),0) -> 3506 | Q6: =P6*10/60 -> 584.33333 | R6: =MAX(0,'1 Relationship'!$Q$4+'1 Relationship'!$Q$3*I6) -> 8.1849978 | S6: =ROUND(R6*2,0)/2 -> 8 | T6: =IFERROR(VLOOKUP(S6,'Power curve'!$A$2:$D$53,4,FALSE()),0) -> 2527 | U6: =T6*10/60 -> 421.16667
A7: 46266.021 | B7: 8.551 | C7: 8.451 | D7: 8.589 | E7: 8.667 | F7: 9.165 | G7: 11.2 | H7: 11 | I7: =AVERAGE(B7:H7) -> 9.3747143 | J7: =MAX(0,'1 Relationship'!$O$4+'1 Relationship'!$O$3*I7) -> 7.8023094 | K7: =ROUND(J7*2,0)/2 -> 8 | L7: =IFERROR(VLOOKUP(K7,'Power curve'!$A$2:$B$53,2,FALSE()),0) -> 2527 | M7: =L7*10/60 -> 421.16667 | N7: =MAX(0,'1 Relationship'!$P$4+'1 Relationship'!$P$3*I7) -> 8.480253 | O7: =ROUND(N7*2,0)/2 -> 8.5 | P7: =IFERROR(VLOOKUP(O7,'Power curve'!$A$2:$C$53,3,FALSE()),0) -> 3016 | Q7: =P7*10/60 -> 502.66667 | R7: =MAX(0,'1 Relationship'!$Q$4+'1 Relationship'!$Q$3*I7) -> 7.8087315 | S7: =ROUND(R7*2,0)/2 -> 8 | T7: =IFERROR(VLOOKUP(S7,'Power curve'!$A$2:$D$53,4,FALSE()),0) -> 2527 | U7: =T7*10/60 -> 421.16667
A8: 46266.028 | B8: 9.33 | C8: 8.879 | D8: 9.531 | E8: 8.931 | F8: 9.393 | G8: 11.8 | H8: 11.3 | I8: =AVERAGE(B8:H8) -> 9.8805714 | J8: =MAX(0,'1 Relationship'!$O$4+'1 Relationship'!$O$3*I8) -> 8.1717468 | K8: =ROUND(J8*2,0)/2 -> 8 | L8: =IFERROR(VLOOKUP(K8,'Power curve'!$A$2:$B$53,2,FALSE()),0) -> 2527 | M8: =L8*10/60 -> 421.16667 | N8: =MAX(0,'1 Relationship'!$P$4+'1 Relationship'!$P$3*I8) -> 8.9062834 | O8: =ROUND(N8*2,0)/2 -> 9 | P8: =IFERROR(VLOOKUP(O8,'Power curve'!$A$2:$C$53,3,FALSE()),0) -> 3506 | Q8: =P8*10/60 -> 584.33333 | R8: =MAX(0,'1 Relationship'!$Q$4+'1 Relationship'!$Q$3*I8) -> 8.1860634 | S8: =ROUND(R8*2,0)/2 -> 8 | T8: =IFERROR(VLOOKUP(S8,'Power curve'!$A$2:$D$53,4,FALSE()),0) -> 2527 | U8: =T8*10/60 -> 421.16667
A9: 46266.035 | B9: 8.642 | C9: 8.091 | D9: 8.62 | E9: 8.722 | F9: 8.929 | G9: 11.7 | H9: 11.5 | I9: =AVERAGE(B9:H9) -> 9.4577143 | J9: =MAX(0,'1 Relationship'!$O$4+'1 Relationship'!$O$3*I9) -> 7.8629259 | K9: =ROUND(J9*2,0)/2 -> 8 | L9: =IFERROR(VLOOKUP(K9,'Power curve'!$A$2:$B$53,2,FALSE()),0) -> 2527 | M9: =L9*10/60 -> 421.16667 | N9: =MAX(0,'1 Relationship'!$P$4+'1 Relationship'!$P$3*I9) -> 8.5501552 | O9: =ROUND(N9*2,0)/2 -> 8.5 | P9: =IFERROR(VLOOKUP(O9,'Power curve'!$A$2:$C$53,3,FALSE()),0) -> 3016 | Q9: =P9*10/60 -> 502.66667 | R9: =MAX(0,'1 Relationship'!$Q$4+'1 Relationship'!$Q$3*I9) -> 7.8706434 | S9: =ROUND(R9*2,0)/2 -> 8 | T9: =IFERROR(VLOOKUP(S9,'Power curve'!$A$2:$D$53,4,FALSE()),0) -> 2527 | U9: =T9*10/60 -> 421.16667
A10: 46266.042 | B10: 7.908 | C10: 8.276 | D10: 8.602 | E10: 7.951 | F10: 8.428 | G10: 11.6 | H10: 12 | I10: =AVERAGE(B10:H10) -> 9.2521429 | J10: =MAX(0,'1 Relationship'!$O$4+'1 Relationship'!$O$3*I10) -> 7.7127931 | K10: =ROUND(J10*2,0)/2 -> 7.5 | L10: =IFERROR(VLOOKUP(K10,'Power curve'!$A$2:$B$53,2,FALSE()),0) -> 2083 | M10: =L10*10/60 -> 347.16667 | N10: =MAX(0,'1 Relationship'!$P$4+'1 Relationship'!$P$3*I10) -> 8.3770239 | O10: =ROUND(N10*2,0)/2 -> 8.5 | P10: =IFERROR(VLOOKUP(O10,'Power curve'!$A$2:$C$53,3,FALSE()),0) -> 3016 | Q10: =P10*10/60 -> 502.66667 | R10: =MAX(0,'1 Relationship'!$Q$4+'1 Relationship'!$Q$3*I10) -> 7.7173023 | S10: =ROUND(R10*2,0)/2 -> 7.5 | T10: =IFERROR(VLOOKUP(S10,'Power curve'!$A$2:$D$53,4,FALSE()),0) -> 2083 | U10: =T10*10/60 -> 347.16667
A11: 46266.049 | B11: 8.658 | C11: 7.72 | D11: 8.876 | E11: 8.587 | F11: 8.62 | G11: 10.6 | H11: 9.9 | I11: =AVERAGE(B11:H11) -> 8.9944286 | J11: =MAX(0,'1 Relationship'!$O$4+'1 Relationship'!$O$3*I11) -> 7.5245792 | K11: =ROUND(J11*2,0)/2 -> 7.5 | L11: =IFERROR(VLOOKUP(K11,'Power curve'!$A$2:$B$53,2,FALSE()),0) -> 2083 | M11: =L11*10/60 -> 347.16667 | N11: =MAX(0,'1 Relationship'!$P$4+'1 Relationship'!$P$3*I11) -> 8.1599782 | O11: =ROUND(N11*2,0)/2 -> 8 | P11: =IFERROR(VLOOKUP(O11,'Power curve'!$A$2:$C$53,3,FALSE()),0) -> 2527 | Q11: =P11*10/60 -> 421.16667 | R11: =MAX(0,'1 Relationship'!$Q$4+'1 Relationship'!$Q$3*I11) -> 7.5250666 | S11: =ROUND(R11*2,0)/2 -> 7.5 | T11: =IFERROR(VLOOKUP(S11,'Power curve'!$A$2:$D$53,4,FALSE()),0) -> 2083 | U11: =T11*10/60 -> 347.16667
A12: 46266.056 | B12: 8.683 | C12: 6.788 | D12: 8.943 | E12: 8.948 | F12: 9.571 | G12: 10.3 | H12: 9.4 | I12: =AVERAGE(B12:H12) -> 8.9475714 | J12: =MAX(0,'1 Relationship'!$O$4+'1 Relationship'!$O$3*I12) -> 7.4903586 | K12: =ROUND(J12*2,0)/2 -> 7.5 | L12: =IFERROR(VLOOKUP(K12,'Power curve'!$A$2:$B$53,2,FALSE()),0) -> 2083 | M12: =L12*10/60 -> 347.16667 | N12: =MAX(0,'1 Relationship'!$P$4+'1 Relationship'!$P$3*I12) -> 8.1205154 | O12: =ROUND(N12*2,0)/2 -> 8 | P12: =IFERROR(VLOOKUP(O12,'Power curve'!$A$2:$C$53,3,FALSE()),0) -> 2527 | Q12: =P12*10/60 -> 421.16667 | R12: =MAX(0,'1 Relationship'!$Q$4+'1 Relationship'!$Q$3*I12) -> 7.4901147 | S12: =ROUND(R12*2,0)/2 -> 7.5 | T12: =IFERROR(VLOOKUP(S12,'Power curve'!$A$2:$D$53,4,FALSE()),0) -> 2083 | U12: =T12*10/60 -> 347.16667
A13: 46266.062 | B13: 9.192 | C13: 7.224 | D13: 10.248 | E13: 9.524 | F13: 9.372 | G13: 10.2 | H13: 9.4 | I13: =AVERAGE(B13:H13) -> 9.3085714 | J13: =MAX(0,'1 Relationship'!$O$4+'1 Relationship'!$O$3*I13) -> 7.754004 | K13: =ROUND(J13*2,0)/2 -> 8 | L13: =IFERROR(VLOOKUP(K13,'Power curve'!$A$2:$B$53,2,FALSE()),0) -> 2527 | M13: =L13*10/60 -> 421.16667 | N13: =MAX(0,'1 Relationship'!$P$4+'1 Relationship'!$P$3*I13) -> 8.4245478 | O13: =ROUND(N13*2,0)/2 -> 8.5 | P13: =IFERROR(VLOOKUP(O13,'Power curve'!$A$2:$C$53,3,FALSE()),0) -> 3016 | Q13: =P13*10/60 -> 502.66667 | R13: =MAX(0,'1 Relationship'!$Q$4+'1 Relationship'!$Q$3*I13) -> 7.7593939 | S13: =ROUND(R13*2,0)/2 -> 8 | T13: =IFERROR(VLOOKUP(S13,'Power curve'!$A$2:$D$53,4,FALSE()),0) -> 2527 | U13: =T13*10/60 -> 421.16667
A14: 46266.069 | B14: 9.503 | C14: 7.526 | D14: 10.444 | E14: 8.985 | F14: 10.097 | G14: 9.8 | H14: 9.7 | I14: =AVERAGE(B14:H14) -> 9.4364286 | J14: =MAX(0,'1 Relationship'!$O$4+'1 Relationship'!$O$3*I14) -> 7.8473805 | K14: =ROUND(J14*2,0)/2 -> 8 | L14: =IFERROR(VLOOKUP(K14,'Power curve'!$A$2:$B$53,2,FALSE()),0) -> 2527 | M14: =L14*10/60 -> 421.16667 | N14: =MAX(0,'1 Relationship'!$P$4+'1 Relationship'!$P$3*I14) -> 8.5322285 | O14: =ROUND(N14*2,0)/2 -> 8.5 | P14: =IFERROR(VLOOKUP(O14,'Power curve'!$A$2:$C$53,3,FALSE()),0) -> 3016 | Q14: =P14*10/60 -> 502.66667 | R14: =MAX(0,'1 Relationship'!$Q$4+'1 Relationship'!$Q$3*I14) -> 7.8547658 | S14: =ROUND(R14*2,0)/2 -> 8 | T14: =IFERROR(VLOOKUP(S14,'Power curve'!$A$2:$D$53,4,FALSE()),0) -> 2527 | U14: =T14*10/60 -> 421.16667
A15: 46266.076 | B15: 9.745 | C15: 6.978 | D15: 10.063 | E15: 10.437 | F15: 10.33 | G15: 9.5 | H15: 9.3 | I15: =AVERAGE(B15:H15) -> 9.479 | J15: =MAX(0,'1 Relationship'!$O$4+'1 Relationship'!$O$3*I15) -> 7.8784713 | K15: =ROUND(J15*2,0)/2 -> 8 | L15: =IFERROR(VLOOKUP(K15,'Power curve'!$A$2:$B$53,2,FALSE()),0) -> 2527 | M15: =L15*10/60 -> 421.16667 | N15: =MAX(0,'1 Relationship'!$P$4+'1 Relationship'!$P$3*I15) -> 8.5680819 | O15: =ROUND(N15*2,0)/2 -> 8.5 | P15: =IFERROR(VLOOKUP(O15,'Power curve'!$A$2:$C$53,3,FALSE()),0) -> 3016 | Q15: =P15*10/60 -> 502.66667 | R15: =MAX(0,'1 Relationship'!$Q$4+'1 Relationship'!$Q$3*I15) -> 7.8865209 | S15: =ROUND(R15*2,0)/2 -> 8 | T15: =IFERROR(VLOOKUP(S15,'Power curve'!$A$2:$D$53,4,FALSE()),0) -> 2527 | U15: =T15*10/60 -> 421.16667
... A27: 46266.16 | B27: 8.903 | C27: 7.146 | D27: 8.922 | E27: 8.363 | F27: 9.434 | G27: 8.6 | H27: 8.3 | I27: =AVERAGE(B27:H27) -> 8.524 | J27: =MAX(0,'1 Relationship'!$O$4+'1 Relationship'!$O$3*I27) -> 7.181016 | K27: =ROUND(J27*2,0)/2 -> 7 | L27: =IFERROR(VLOOKUP(K27,'Power curve'!$A$2:$B$53,2,FALSE()),0) -> 1691 | M27: =L27*10/60 -> 281.83333 | N27: =MAX(0,'1 Relationship'!$P$4+'1 Relationship'!$P$3*I27) -> 7.7637856 | O27: =ROUND(N27*2,0)/2 -> 8 | P27: =IFERROR(VLOOKUP(O27,'Power curve'!$A$2:$C$53,3,FALSE()),0) -> 2527 | Q27: =P27*10/60 -> 421.16667 | R27: =MAX(0,'1 Relationship'!$Q$4+'1 Relationship'!$Q$3*I27) -> 7.1741618 | S27: =ROUND(R27*2,0)/2 -> 7 | T27: =IFERROR(VLOOKUP(S27,'Power curve'!$A$2:$D$53,4,FALSE()),0) -> 1691 | U27: =T27*10/60 -> 281.83333
A28: 46266.167 | B28: 8.069 | C28: 5.634 | D28: 8.652 | E28: 8.713 | F28: 8.681 | G28: 8.8 | H28: 8.8 | I28: =AVERAGE(B28:H28) -> 8.1927143 | J28: =MAX(0,'1 Relationship'!$O$4+'1 Relationship'!$O$3*I28) -> 6.9390715 | K28: =ROUND(J28*2,0)/2 -> 7 | L28: =IFERROR(VLOOKUP(K28,'Power curve'!$A$2:$B$53,2,FALSE()),0) -> 1691 | M28: =L28*10/60 -> 281.83333 | N28: =MAX(0,'1 Relationship'!$P$4+'1 Relationship'!$P$3*I28) -> 7.4847784 | O28: =ROUND(N28*2,0)/2 -> 7.5 | P28: =IFERROR(VLOOKUP(O28,'Power curve'!$A$2:$C$53,3,FALSE()),0) -> 2083 | Q28: =P28*10/60 -> 347.16667 | R28: =MAX(0,'1 Relationship'!$Q$4+'1 Relationship'!$Q$3*I28) -> 6.9270472 | S28: =ROUND(R28*2,0)/2 -> 7 | T28: =IFERROR(VLOOKUP(S28,'Power curve'!$A$2:$D$53,4,FALSE()),0) -> 1691 | U28: =T28*10/60 -> 281.83333 | X28: 2 · Fill the gap (1–3 Sep) and turn wind into energy
A29: 46266.174 | B29: 7.858 | C29: 6.915 | D29: 8.313 | E29: 7.945 | F29: 9.057 | G29: 8.9 | H29: 8.8 | I29: =AVERAGE(B29:H29) -> 8.2554286 | J29: =MAX(0,'1 Relationship'!$O$4+'1 Relationship'!$O$3*I29) -> 6.984873 | K29: =ROUND(J29*2,0)/2 -> 7 | L29: =IFERROR(VLOOKUP(K29,'Power curve'!$A$2:$B$53,2,FALSE()),0) -> 1691 | M29: =L29*10/60 -> 281.83333 | N29: =MAX(0,'1 Relationship'!$P$4+'1 Relationship'!$P$3*I29) -> 7.537596 | O29: =ROUND(N29*2,0)/2 -> 7.5 | P29: =IFERROR(VLOOKUP(O29,'Power curve'!$A$2:$C$53,3,FALSE()),0) -> 2083 | Q29: =P29*10/60 -> 347.16667 | R29: =MAX(0,'1 Relationship'!$Q$4+'1 Relationship'!$Q$3*I29) -> 6.9738274 | S29: =ROUND(R29*2,0)/2 -> 7 | T29: =IFERROR(VLOOKUP(S29,'Power curve'!$A$2:$D$53,4,FALSE()),0) -> 1691 | U29: =T29*10/60 -> 281.83333 | X29: For every 10 minutes of the outage: take the neighbours' average (col I), apply each turbine's rule from tab 1 → predicted wind, look up the power in the power curve, then energy = power × 10/60 h. Totals per turbine are on the Summary tab.
A30: 46266.181 | B30: 8.03 | C30: 5.709 | D30: 7.817 | E30: 7.245 | F30: 8.173 | G30: 8.5 | H30: 7.9 | I30: =AVERAGE(B30:H30) -> 7.6248571 | J30: =MAX(0,'1 Relationship'!$O$4+'1 Relationship'!$O$3*I30) -> 6.5243543 | K30: =ROUND(J30*2,0)/2 -> 6.5 | L30: =IFERROR(VLOOKUP(K30,'Power curve'!$A$2:$B$53,2,FALSE()),0) -> 1349 | M30: =L30*10/60 -> 224.83333 | N30: =MAX(0,'1 Relationship'!$P$4+'1 Relationship'!$P$3*I30) -> 7.0065319 | O30: =ROUND(N30*2,0)/2 -> 7 | P30: =IFERROR(VLOOKUP(O30,'Power curve'!$A$2:$C$53,3,FALSE()),0) -> 1691 | Q30: =P30*10/60 -> 281.83333 | R30: =MAX(0,'1 Relationship'!$Q$4+'1 Relationship'!$Q$3*I30) -> 6.503468 | S30: =ROUND(R30*2,0)/2 -> 6.5 | T30: =IFERROR(VLOOKUP(S30,'Power curve'!$A$2:$D$53,4,FALSE()),0) -> 1349 | U30: =T30*10/60 -> 224.83333
A31: 46266.188 | B31: 7.62 | C31: 7.479 | D31: 7.897 | E31: 7.879 | F31: 8.274 | G31: 8.9 | H31: 8.2 | I31: =AVERAGE(B31:H31) -> 8.0355714 | J31: =MAX(0,'1 Relationship'!$O$4+'1 Relationship'!$O$3*I31) -> 6.824307 | K31: =ROUND(J31*2,0)/2 -> 7 | L31: =IFERROR(VLOOKUP(K31,'Power curve'!$A$2:$B$53,2,FALSE()),0) -> 1691 | M31: =L31*10/60 -> 281.83333 | N31: =MAX(0,'1 Relationship'!$P$4+'1 Relationship'!$P$3*I31) -> 7.3524334 | O31: =ROUND(N31*2,0)/2 -> 7.5 | P31: =IFERROR(VLOOKUP(O31,'Power curve'!$A$2:$C$53,3,FALSE()),0) -> 2083 | Q31: =P31*10/60 -> 347.16667 | R31: =MAX(0,'1 Relationship'!$Q$4+'1 Relationship'!$Q$3*I31) -> 6.8098303 | S31: =ROUND(R31*2,0)/2 -> 7 | T31: =IFERROR(VLOOKUP(S31,'Power curve'!$A$2:$D$53,4,FALSE()),0) -> 1691 | U31: =T31*10/60 -> 281.83333
A32: 46266.194 | B32: 7.86 | C32: 7.333 | D32: 8.191 | E32: 7.562 | F32: 8.355 | G32: 8.8 | H32: 8.6 | I32: =AVERAGE(B32:H32) -> 8.1001429 | J32: =MAX(0,'1 Relationship'!$O$4+'1 Relationship'!$O$3*I32) -> 6.8714648 | K32: =ROUND(J32*2,0)/2 -> 7 | L32: =IFERROR(VLOOKUP(K32,'Power curve'!$A$2:$B$53,2,FALSE()),0) -> 1691 | M32: =L32*10/60 -> 281.83333 | N32: =MAX(0,'1 Relationship'!$P$4+'1 Relationship'!$P$3*I32) -> 7.4068152 | O32: =ROUND(N32*2,0)/2 -> 7.5 | P32: =IFERROR(VLOOKUP(O32,'Power curve'!$A$2:$C$53,3,FALSE()),0) -> 2083 | Q32: =P32*10/60 -> 347.16667 | R32: =MAX(0,'1 Relationship'!$Q$4+'1 Relationship'!$Q$3*I32) -> 6.8579958 | S32: =ROUND(R32*2,0)/2 -> 7 | T32: =IFERROR(VLOOKUP(S32,'Power curve'!$A$2:$D$53,4,FALSE()),0) -> 1691 | U32: =T32*10/60 -> 281.83333
A33: 46266.201 | B33: 8.542 | C33: 7.741 | D33: 7.944 | E33: 7.359 | F33: 8.827 | G33: 8.6 | H33: 8.3 | I33: =AVERAGE(B33:H33) -> 8.1875714 | J33: =MAX(0,'1 Relationship'!$O$4+'1 Relationship'!$O$3*I33) -> 6.9353156 | K33: =ROUND(J33*2,0)/2 -> 7 | L33: =IFERROR(VLOOKUP(K33,'Power curve'!$A$2:$B$53,2,FALSE()),0) -> 1691 | M33: =L33*10/60 -> 281.83333 | N33: =MAX(0,'1 Relationship'!$P$4+'1 Relationship'!$P$3*I33) -> 7.4804471 | O33: =ROUND(N33*2,0)/2 -> 7.5 | P33: =IFERROR(VLOOKUP(O33,'Power curve'!$A$2:$C$53,3,FALSE()),0) -> 2083 | Q33: =P33*10/60 -> 347.16667 | R33: =MAX(0,'1 Relationship'!$Q$4+'1 Relationship'!$Q$3*I33) -> 6.9232111 | S33: =ROUND(R33*2,0)/2 -> 7 | T33: =IFERROR(VLOOKUP(S33,'Power curve'!$A$2:$D$53,4,FALSE()),0) -> 1691 | U33: =T33*10/60 -> 281.83333
A34: 46266.208 | B34: 7.803 | C34: 6.887 | D34: 7.845 | E34: 7.846 | F34: 8.417 | G34: 8.5 | H34: 8.1 | I34: =AVERAGE(B34:H34) -> 7.914 | J34: =MAX(0,'1 Relationship'!$O$4+'1 Relationship'!$O$3*I34) -> 6.735521 | K34: =ROUND(J34*2,0)/2 -> 6.5 | L34: =IFERROR(VLOOKUP(K34,'Power curve'!$A$2:$B$53,2,FALSE()),0) -> 1349 | M34: =L34*10/60 -> 224.83333 | N34: =MAX(0,'1 Relationship'!$P$4+'1 Relationship'!$P$3*I34) -> 7.2500466 | O34: =ROUND(N34*2,0)/2 -> 7.5 | P34: =IFERROR(VLOOKUP(O34,'Power curve'!$A$2:$C$53,3,FALSE()),0) -> 2083 | Q34: =P34*10/60 -> 347.16667 | R34: =MAX(0,'1 Relationship'!$Q$4+'1 Relationship'!$Q$3*I34) -> 6.7191471 | S34: =ROUND(R34*2,0)/2 -> 6.5 | T34: =IFERROR(VLOOKUP(S34,'Power curve'!$A$2:$D$53,4,FALSE()),0) -> 1349 | U34: =T34*10/60 -> 224.83333
A35: 46266.215 | B35: 7.986 | C35: 7.444 | D35: 8.632 | E35: 8.357 | F35: 8.741 | G35: 8.6 | H35: 8.3 | I35: =AVERAGE(B35:H35) -> 8.2942857 | J35: =MAX(0,'1 Relationship'!$O$4+'1 Relationship'!$O$3*I35) -> 7.0132512 | K35: =ROUND(J35*2,0)/2 -> 7 | L35: =IFERROR(VLOOKUP(K35,'Power curve'!$A$2:$B$53,2,FALSE()),0) -> 1691 | M35: =L35*10/60 -> 281.83333 | N35: =MAX(0,'1 Relationship'!$P$4+'1 Relationship'!$P$3*I35) -> 7.5703213 | O35: =ROUND(N35*2,0)/2 -> 7.5 | P35: =IFERROR(VLOOKUP(O35,'Power curve'!$A$2:$C$53,3,FALSE()),0) -> 2083 | Q35: =P35*10/60 -> 347.16667 | R35: =MAX(0,'1 Relationship'!$Q$4+'1 Relationship'!$Q$3*I35) -> 7.002812 | S35: =ROUND(R35*2,0)/2 -> 7 | T35: =IFERROR(VLOOKUP(S35,'Power curve'!$A$2:$D$53,4,FALSE()),0) -> 1691 | U35: =T35*10/60 -> 281.83333
A36: 46266.222 | B36: 8.453 | C36: 6.085 | D36: 8.732 | E36: 7.58 | F36: 8.938 | G36: 8.5 | H36: 8.6 | I36: =AVERAGE(B36:H36) -> 8.1268571 | J36: =MAX(0,'1 Relationship'!$O$4+'1 Relationship'!$O$3*I36) -> 6.8909748 | K36: =ROUND(J36*2,0)/2 -> 7 | L36: =IFERROR(VLOOKUP(K36,'Power curve'!$A$2:$B$53,2,FALSE()),0) -> 1691 | M36: =L36*10/60 -> 281.83333 | N36: =MAX(0,'1 Relationship'!$P$4+'1 Relationship'!$P$3*I36) -> 7.4293138 | O36: =ROUND(N36*2,0)/2 -> 7.5 | P36: =IFERROR(VLOOKUP(O36,'Power curve'!$A$2:$C$53,3,FALSE()),0) -> 2083 | Q36: =P36*10/60 -> 347.16667 | R36: =MAX(0,'1 Relationship'!$Q$4+'1 Relationship'!$Q$3*I36) -> 6.8779227 | S36: =ROUND(R36*2,0)/2 -> 7 | T36: =IFERROR(VLOOKUP(S36,'Power curve'!$A$2:$D$53,4,FALSE()),0) -> 1691 | U36: =T36*10/60 -> 281.83333
A37: 46266.229 | B37: 7.84 | C37: 5.856 | D37: 8.397 | E37: 8.152 | F37: 8.102 | G37: 8.5 | H37: 8.1 | I37: =AVERAGE(B37:H37) -> 7.8495714 | J37: =MAX(0,'1 Relationship'!$O$4+'1 Relationship'!$O$3*I37) -> 6.6884676 | K37: =ROUND(J37*2,0)/2 -> 6.5 | L37: =IFERROR(VLOOKUP(K37,'Power curve'!$A$2:$B$53,2,FALSE()),0) -> 1349 | M37: =L37*10/60 -> 224.83333 | N37: =MAX(0,'1 Relationship'!$P$4+'1 Relationship'!$P$3*I37) -> 7.1957851 | O37: =ROUND(N37*2,0)/2 -> 7 | P37: =IFERROR(VLOOKUP(O37,'Power curve'!$A$2:$C$53,3,FALSE()),0) -> 1691 | Q37: =P37*10/60 -> 281.83333 | R37: =MAX(0,'1 Relationship'!$Q$4+'1 Relationship'!$Q$3*I37) -> 6.6710881 | S37: =ROUND(R37*2,0)/2 -> 6.5 | T37: =IFERROR(VLOOKUP(S37,'Power curve'!$A$2:$D$53,4,FALSE()),0) -> 1349 | U37: =T37*10/60 -> 224.83333
A38: 46266.236 | B38: 7.491 | C38: 5.803 | D38: 7.67 | E38: 7.469 | F38: 7.517 | G38: 8.6 | H38: 8.2 | I38: =AVERAGE(B38:H38) -> 7.5357143 | J38: =MAX(0,'1 Relationship'!$O$4+'1 Relationship'!$O$3*I38) -> 6.4592515 | K38: =ROUND(J38*2,0)/2 -> 6.5 | L38: =IFERROR(VLOOKUP(K38,'Power curve'!$A$2:$B$53,2,FALSE()),0) -> 1349 | M38: =L38*10/60 -> 224.83333 | N38: =MAX(0,'1 Relationship'!$P$4+'1 Relationship'!$P$3*I38) -> 6.9314562 | O38: =ROUND(N38*2,0)/2 -> 7 | P38: =IFERROR(VLOOKUP(O38,'Power curve'!$A$2:$C$53,3,FALSE()),0) -> 1691 | Q38: =P38*10/60 -> 281.83333 | R38: =MAX(0,'1 Relationship'!$Q$4+'1 Relationship'!$Q$3*I38) -> 6.436974 | S38: =ROUND(R38*2,0)/2 -> 6.5 | T38: =IFERROR(VLOOKUP(S38,'Power curve'!$A$2:$D$53,4,FALSE()),0) -> 1349 | U38: =T38*10/60 -> 224.83333
A39: 46266.243 | B39: 7.284 | C39: 5.412 | D39: 8.053 | E39: 6.975 | F39: 8.226 | G39: 8.8 | H39: 8.7 | I39: =AVERAGE(B39:H39) -> 7.6357143 | J39: =MAX(0,'1 Relationship'!$O$4+'1 Relationship'!$O$3*I39) -> 6.5322835 | K39: =ROUND(J39*2,0)/2 -> 6.5 | L39: =IFERROR(VLOOKUP(K39,'Power curve'!$A$2:$B$53,2,FALSE()),0) -> 1349 | M39: =L39*10/60 -> 224.83333 | N39: =MAX(0,'1 Relationship'!$P$4+'1 Relationship'!$P$3*I39) -> 7.0156757 | O39: =ROUND(N39*2,0)/2 -> 7 | P39: =IFERROR(VLOOKUP(O39,'Power curve'!$A$2:$C$53,3,FALSE()),0) -> 1691 | Q39: =P39*10/60 -> 281.83333 | R39: =MAX(0,'1 Relationship'!$Q$4+'1 Relationship'!$Q$3*I39) -> 6.5115666 | S39: =ROUND(R39*2,0)/2 -> 6.5 | T39: =IFERROR(VLOOKUP(S39,'Power curve'!$A$2:$D$53,4,FALSE()),0) -> 1349 | U39: =T39*10/60 -> 224.83333
A40: 46266.25 | B40: 7.185 | C40: 6.19 | D40: 7.667 | E40: 7.318 | F40: 7.666 | G40: 8.8 | H40: 8.1 | I40: =AVERAGE(B40:H40) -> 7.5608571 | J40: =MAX(0,'1 Relationship'!$O$4+'1 Relationship'!$O$3*I40) -> 6.4776138 | K40: =ROUND(J40*2,0)/2 -> 6.5 | L40: =IFERROR(VLOOKUP(K40,'Power curve'!$A$2:$B$53,2,FALSE()),0) -> 1349 | M40: =L40*10/60 -> 224.83333 | N40: =MAX(0,'1 Relationship'!$P$4+'1 Relationship'!$P$3*I40) -> 6.9526314 | O40: =ROUND(N40*2,0)/2 -> 7 | P40: =IFERROR(VLOOKUP(O40,'Power curve'!$A$2:$C$53,3,FALSE()),0) -> 1691 | Q40: =P40*10/60 -> 281.83333 | R40: =MAX(0,'1 Relationship'!$Q$4+'1 Relationship'!$Q$3*I40) -> 6.4557287 | S40: =ROUND(R40*2,0)/2 -> 6.5 | T40: =IFERROR(VLOOKUP(S40,'Power curve'!$A$2:$D$53,4,FALSE()),0) -> 1349 | U40: =T40*10/60 -> 224.83333
A41: 46266.257 | B41: 7.256 | C41: 6.048 | D41: 7.677 | E41: 6.451 | F41: 7.979 | G41: 9 | H41: 8.2 | I41: =AVERAGE(B41:H41) -> 7.5158571 | J41: =MAX(0,'1 Relationship'!$O$4+'1 Relationship'!$O$3*I41) -> 6.4447495 | K41: =ROUND(J41*2,0)/2 -> 6.5 | L41: =IFERROR(VLOOKUP(K41,'Power curve'!$A$2:$B$53,2,FALSE()),0) -> 1349 | M41: =L41*10/60 -> 224.83333 | N41: =MAX(0,'1 Relationship'!$P$4+'1 Relationship'!$P$3*I41) -> 6.9147326 | O41: =ROUND(N41*2,0)/2 -> 7 | P41: =IFERROR(VLOOKUP(O41,'Power curve'!$A$2:$C$53,3,FALSE()),0) -> 1691 | Q41: =P41*10/60 -> 281.83333 | R41: =MAX(0,'1 Relationship'!$Q$4+'1 Relationship'!$Q$3*I41) -> 6.422162 | S41: =ROUND(R41*2,0)/2 -> 6.5 | T41: =IFERROR(VLOOKUP(S41,'Power curve'!$A$2:$D$53,4,FALSE()),0) -> 1349 | U41: =T41*10/60 -> 224.83333
... A435: 46268.993 | B435: 7.66 | C435: 5.557 | D435: 8.194 | E435: 7.614 | F435: 8.482 | G435: 7.6 | H435: 7.2 | I435: =AVERAGE(B435:H435) -> 7.4724286 | J435: =MAX(0,'1 Relationship'!$O$4+'1 Relationship'!$O$3*I435) -> 6.4130327 | K435: =ROUND(J435*2,0)/2 -> 6.5 | L435: =IFERROR(VLOOKUP(K435,'Power curve'!$A$2:$B$53,2,FALSE()),0) -> 1349 | M435: =L435*10/60 -> 224.83333 | N435: =MAX(0,'1 Relationship'!$P$4+'1 Relationship'!$P$3*I435) -> 6.8781573 | O435: =ROUND(N435*2,0)/2 -> 7 | P435: =IFERROR(VLOOKUP(O435,'Power curve'!$A$2:$C$53,3,FALSE()),0) -> 1691 | Q435: =P435*10/60 -> 281.83333 | R435: =MAX(0,'1 Relationship'!$Q$4+'1 Relationship'!$Q$3*I435) -> 6.3897676 | S435: =ROUND(R435*2,0)/2 -> 6.5 | T435: =IFERROR(VLOOKUP(S435,'Power curve'!$A$2:$D$53,4,FALSE()),0) -> 1349 | U435: =T435*10/60 -> 224.83333

Sheet 3 Check
A1: Timestamp | B1: H1 | C1: H2 | D1: H3 | E1: H4 | F1: H5 | G1: O1 | H1: O2 | I1: Neighbours average (m/s) | J1: Predicted wind (m/s) | K1: Rounded to 0.5 | L1: Predicted power (kW) | M1: Predicted energy (kWh) | N1: Measured wind (m/s) | O1: Wind error (m/s) | P1: Abs. wind error | Q1: Measured power (kW) | R1: Power error (kW) | S1: Abs. power error | T1: Measured energy (kWh) | U1: Predicted energy, same rows (kWh) | V1: Predicted wind (m/s) | W1: Rounded to 0.5 | X1: Predicted power (kW) | Y1: Predicted energy (kWh) | Z1: Measured wind (m/s) | AA1: Wind error (m/s) | AB1: Abs. wind error | AC1: Measured power (kW) | AD1: Power error (kW) | AE1: Abs. power error | AF1: Measured energy (kWh) | AG1: Predicted energy, same rows (kWh) | AH1: Predicted wind (m/s) | AI1: Rounded to 0.5 | AJ1: Predicted power (kW) | AK1: Predicted energy (kWh) | AL1: Measured wind (m/s) | AM1: Wind error (m/s) | AN1: Abs. wind error | AO1: Measured power (kW) | AP1: Power error (kW) | AQ1: Abs. power error | AR1: Measured energy (kWh) | AS1: Predicted energy, same rows (kWh)
A2: every 10 min | B2: Neighbouring turbines, m/s | I2: Formula: AVERAGE of the 7 | J2: Formula: intercept + slope × neighbours (rule from tab 1) | K2: Power curve has 0.5 m/s steps, so we round to look it up | L2: VLOOKUP in the power curve | M2: kW × 10/60 h: energy in this 10-min slot (like km/h × hours = km) | N2: What the turbine really measured | O2: Predicted − measured (+ = too high) | P2: Error without the sign → for MAE | Q2: Power curve lookup of the REAL wind | R2: Predicted − measured power | S2: Without sign → for power MAE | T2: What the turbine really would have made | U2: Our prediction, only where a real value exists → fair comparison | V2: Formula: intercept + slope × neighbours (rule from tab 1) | W2: Power curve has 0.5 m/s steps, so we round to look it up | X2: VLOOKUP in the power curve | Y2: kW × 10/60 h: energy in this 10-min slot (like km/h × hours = km) | Z2: What the turbine really measured | AA2: Predicted − measured (+ = too high) | AB2: Error without the sign → for MAE | AC2: Power curve lookup of the REAL wind | AD2: Predicted − measured power | AE2: Without sign → for power MAE | AF2: What the turbine really would have made | AG2: Our prediction, only where a real value exists → fair comparison | AH2: Formula: intercept + slope × neighbours (rule from tab 1) | AI2: Power curve has 0.5 m/s steps, so we round to look it up | AJ2: VLOOKUP in the power curve | AK2: kW × 10/60 h: energy in this 10-min slot (like km/h × hours = km) | AL2: What the turbine really measured | AM2: Predicted − measured (+ = too high) | AN2: Error without the sign → for MAE | AO2: Power curve lookup of the REAL wind | AP2: Predicted − measured power | AQ2: Without sign → for power MAE | AR2: What the turbine really would have made | AS2: Our prediction, only where a real value exists → fair comparison
A3: 46269 | B3: 7.984 | C3: 6.282 | D3: 8.063 | E3: 7.883 | F3: 8.827 | G3: 8.3 | H3: 7.9 | I3: =AVERAGE(B3:H3) -> 7.8912857 | J3: =MAX(0,'1 Relationship'!$O$4+'1 Relationship'!$O$3*I3) -> 6.7189323 | K3: =ROUND(J3*2,0)/2 -> 6.5 | L3: =IFERROR(VLOOKUP(K3,'Power curve'!$A$2:$B$53,2,FALSE()),0) -> 1349 | M3: =L3*10/60 -> 224.83333 | N3: 3.928 | O3: =IF(N3="","",J3-N3) -> 2.7909323 | P3: =IF(N3="","",ABS(O3)) -> 2.7909323 | Q3: =IF(N3="","",IFERROR(VLOOKUP(ROUND(N3*2,0)/2,'Power curve'!$A$2:$B$53,2,FALSE()),0)) -> 247 | R3: =IF(N3="","",L3-Q3) -> 1102 | S3: =IF(N3="","",ABS(R3)) -> 1102 | T3: =IF(N3="","",Q3*10/60) -> 41.166667 | U3: =IF(N3="","",M3) -> 224.83333 | V3: =MAX(0,'1 Relationship'!$P$4+'1 Relationship'!$P$3*I3) -> 7.2309167 | W3: =ROUND(V3*2,0)/2 -> 7 | X3: =IFERROR(VLOOKUP(W3,'Power curve'!$A$2:$C$53,3,FALSE()),0) -> 1691 | Y3: =X3*10/60 -> 281.83333 | Z3: 7.195 | AA3: =IF(Z3="","",V3-Z3) -> 0.035916705 | AB3: =IF(Z3="","",ABS(AA3)) -> 0.035916705 | AC3: =IF(Z3="","",IFERROR(VLOOKUP(ROUND(Z3*2,0)/2,'Power curve'!$A$2:$C$53,3,FALSE()),0)) -> 1691 | AD3: =IF(Z3="","",X3-AC3) -> 0 | AE3: =IF(Z3="","",ABS(AD3)) -> 0 | AF3: =IF(Z3="","",AC3*10/60) -> 281.83333 | AG3: =IF(Z3="","",Y3) -> 281.83333 | AH3: =MAX(0,'1 Relationship'!$Q$4+'1 Relationship'!$Q$3*I3) -> 6.7022039 | AI3: =ROUND(AH3*2,0)/2 -> 6.5 | AJ3: =IFERROR(VLOOKUP(AI3,'Power curve'!$A$2:$D$53,4,FALSE()),0) -> 1349 | AK3: =AJ3*10/60 -> 224.83333 | AL3: 4.156 | AM3: =IF(AL3="","",AH3-AL3) -> 2.5462039 | AN3: =IF(AL3="","",ABS(AM3)) -> 2.5462039 | AO3: =IF(AL3="","",IFERROR(VLOOKUP(ROUND(AL3*2,0)/2,'Power curve'!$A$2:$D$53,4,FALSE()),0)) -> 247 | AP3: =IF(AL3="","",AJ3-AO3) -> 1102 | AQ3: =IF(AL3="","",ABS(AP3)) -> 1102 | AR3: =IF(AL3="","",AO3*10/60) -> 41.166667 | AS3: =IF(AL3="","",AK3) -> 224.83333
A4: 46269.007 | B4: 7.512 | C4: 5.822 | D4: 7.456 | E4: 7.611 | F4: 8.177 | G4: 8.6 | H4: 8.4 | I4: =AVERAGE(B4:H4) -> 7.654 | J4: =MAX(0,'1 Relationship'!$O$4+'1 Relationship'!$O$3*I4) -> 6.5456379 | K4: =ROUND(J4*2,0)/2 -> 6.5 | L4: =IFERROR(VLOOKUP(K4,'Power curve'!$A$2:$B$53,2,FALSE()),0) -> 1349 | M4: =L4*10/60 -> 224.83333 | N4: 5.204 | O4: =IF(N4="","",J4-N4) -> 1.3416379 | P4: =IF(N4="","",ABS(O4)) -> 1.3416379 | Q4: =IF(N4="","",IFERROR(VLOOKUP(ROUND(N4*2,0)/2,'Power curve'!$A$2:$B$53,2,FALSE()),0)) -> 584 | R4: =IF(N4="","",L4-Q4) -> 765 | S4: =IF(N4="","",ABS(R4)) -> 765 | T4: =IF(N4="","",Q4*10/60) -> 97.333333 | U4: =IF(N4="","",M4) -> 224.83333 | V4: =MAX(0,'1 Relationship'!$P$4+'1 Relationship'!$P$3*I4) -> 7.0310758 | W4: =ROUND(V4*2,0)/2 -> 7 | X4: =IFERROR(VLOOKUP(W4,'Power curve'!$A$2:$C$53,3,FALSE()),0) -> 1691 | Y4: =X4*10/60 -> 281.83333 | Z4: 7.179 | AA4: =IF(Z4="","",V4-Z4) -> -0.14792416 | AB4: =IF(Z4="","",ABS(AA4)) -> 0.14792416 | AC4: =IF(Z4="","",IFERROR(VLOOKUP(ROUND(Z4*2,0)/2,'Power curve'!$A$2:$C$53,3,FALSE()),0)) -> 1691 | AD4: =IF(Z4="","",X4-AC4) -> 0 | AE4: =IF(Z4="","",ABS(AD4)) -> 0 | AF4: =IF(Z4="","",AC4*10/60) -> 281.83333 | AG4: =IF(Z4="","",Y4) -> 281.83333 | AH4: =MAX(0,'1 Relationship'!$Q$4+'1 Relationship'!$Q$3*I4) -> 6.5252064 | AI4: =ROUND(AH4*2,0)/2 -> 6.5 | AJ4: =IFERROR(VLOOKUP(AI4,'Power curve'!$A$2:$D$53,4,FALSE()),0) -> 1349 | AK4: =AJ4*10/60 -> 224.83333 | AL4: 4.207 | AM4: =IF(AL4="","",AH4-AL4) -> 2.3182064 | AN4: =IF(AL4="","",ABS(AM4)) -> 2.3182064 | AO4: =IF(AL4="","",IFERROR(VLOOKUP(ROUND(AL4*2,0)/2,'Power curve'!$A$2:$D$53,4,FALSE()),0)) -> 247 | AP4: =IF(AL4="","",AJ4-AO4) -> 1102 | AQ4: =IF(AL4="","",ABS(AP4)) -> 1102 | AR4: =IF(AL4="","",AO4*10/60) -> 41.166667 | AS4: =IF(AL4="","",AK4) -> 224.83333 | AU4: =AVERAGE(T3:T866) -> 246.56481 | AV4: Could the rule have worked on days where we KNOW the answer? (4–9 Sep)
A5: 46269.014 | B5: 7.85 | C5: 5.802 | D5: 7.832 | E5: 8.019 | F5: 8.239 | G5: 9 | H5: 8.8 | I5: =AVERAGE(B5:H5) -> 7.9345714 | J5: =MAX(0,'1 Relationship'!$O$4+'1 Relationship'!$O$3*I5) -> 6.7505447 | K5: =ROUND(J5*2,0)/2 -> 7 | L5: =IFERROR(VLOOKUP(K5,'Power curve'!$A$2:$B$53,2,FALSE()),0) -> 1691 | M5: =L5*10/60 -> 281.83333 | N5: 4.681 | O5: =IF(N5="","",J5-N5) -> 2.0695447 | P5: =IF(N5="","",ABS(O5)) -> 2.0695447 | Q5: =IF(N5="","",IFERROR(VLOOKUP(ROUND(N5*2,0)/2,'Power curve'!$A$2:$B$53,2,FALSE()),0)) -> 400 | R5: =IF(N5="","",L5-Q5) -> 1291 | S5: =IF(N5="","",ABS(R5)) -> 1291 | T5: =IF(N5="","",Q5*10/60) -> 66.666667 | U5: =IF(N5="","",M5) -> 281.83333 | V5: =MAX(0,'1 Relationship'!$P$4+'1 Relationship'!$P$3*I5) -> 7.2673717 | W5: =ROUND(V5*2,0)/2 -> 7.5 | X5: =IFERROR(VLOOKUP(W5,'Power curve'!$A$2:$C$53,3,FALSE()),0) -> 2083 | Y5: =X5*10/60 -> 347.16667 | Z5: 6.52 | AA5: =IF(Z5="","",V5-Z5) -> 0.74737172 | AB5: =IF(Z5="","",ABS(AA5)) -> 0.74737172 | AC5: =IF(Z5="","",IFERROR(VLOOKUP(ROUND(Z5*2,0)/2,'Power curve'!$A$2:$C$53,3,FALSE()),0)) -> 1349 | AD5: =IF(Z5="","",X5-AC5) -> 734 | AE5: =IF(Z5="","",ABS(AD5)) -> 734 | AF5: =IF(Z5="","",AC5*10/60) -> 224.83333 | AG5: =IF(Z5="","",Y5) -> 347.16667 | AH5: =MAX(0,'1 Relationship'!$Q$4+'1 Relationship'!$Q$3*I5) -> 6.7344918 | AI5: =ROUND(AH5*2,0)/2 -> 6.5 | AJ5: =IFERROR(VLOOKUP(AI5,'Power curve'!$A$2:$D$53,4,FALSE()),0) -> 1349 | AK5: =AJ5*10/60 -> 224.83333 | AL5: 5.327 | AM5: =IF(AL5="","",AH5-AL5) -> 1.4074918 | AN5: =IF(AL5="","",ABS(AM5)) -> 1.4074918 | AO5: =IF(AL5="","",IFERROR(VLOOKUP(ROUND(AL5*2,0)/2,'Power curve'!$A$2:$D$53,4,FALSE()),0)) -> 800 | AP5: =IF(AL5="","",AJ5-AO5) -> 549 | AQ5: =IF(AL5="","",ABS(AP5)) -> 549 | AR5: =IF(AL5="","",AO5*10/60) -> 133.33333 | AS5: =IF(AL5="","",AK5) -> 224.83333 | AV5: Same calculation as the outage, but for 4–9 Sep where the turbines really measured the wind. These days were NOT used to learn the rule, so this is a fair test. The accuracy numbers (RMSE, MAE, energy deviation) are on the Summary tab.
A6: 46269.021 | B6: 7.284 | C6: 6.519 | D6: 7.762 | E6: 7.352 | F6: 7.719 | G6: 9.7 | H6: 9 | I6: =AVERAGE(B6:H6) -> 7.9051429 | J6: =MAX(0,'1 Relationship'!$O$4+'1 Relationship'!$O$3*I6) -> 6.7290525 | K6: =ROUND(J6*2,0)/2 -> 6.5 | L6: =IFERROR(VLOOKUP(K6,'Power curve'!$A$2:$B$53,2,FALSE()),0) -> 1349 | M6: =L6*10/60 -> 224.83333 | N6: 5.585 | O6: =IF(N6="","",J6-N6) -> 1.1440525 | P6: =IF(N6="","",ABS(O6)) -> 1.1440525 | Q6: =IF(N6="","",IFERROR(VLOOKUP(ROUND(N6*2,0)/2,'Power curve'!$A$2:$B$53,2,FALSE()),0)) -> 800 | R6: =IF(N6="","",L6-Q6) -> 549 | S6: =IF(N6="","",ABS(R6)) -> 549 | T6: =IF(N6="","",Q6*10/60) -> 133.33333 | U6: =IF(N6="","",M6) -> 224.83333 | V6: =MAX(0,'1 Relationship'!$P$4+'1 Relationship'!$P$3*I6) -> 7.2425871 | W6: =ROUND(V6*2,0)/2 -> 7 | X6: =IFERROR(VLOOKUP(W6,'Power curve'!$A$2:$C$53,3,FALSE()),0) -> 1691 | Y6: =X6*10/60 -> 281.83333 | Z6: 6.43 | AA6: =IF(Z6="","",V6-Z6) -> 0.81258712 | AB6: =IF(Z6="","",ABS(AA6)) -> 0.81258712 | AC6: =IF(Z6="","",IFERROR(VLOOKUP(ROUND(Z6*2,0)/2,'Power curve'!$A$2:$C$53,3,FALSE()),0)) -> 1349 | AD6: =IF(Z6="","",X6-AC6) -> 342 | AE6: =IF(Z6="","",ABS(AD6)) -> 342 | AF6: =IF(Z6="","",AC6*10/60) -> 224.83333 | AG6: =IF(Z6="","",Y6) -> 281.83333 | AH6: =MAX(0,'1 Relationship'!$Q$4+'1 Relationship'!$Q$3*I6) -> 6.7125403 | AI6: =ROUND(AH6*2,0)/2 -> 6.5 | AJ6: =IFERROR(VLOOKUP(AI6,'Power curve'!$A$2:$D$53,4,FALSE()),0) -> 1349 | AK6: =AJ6*10/60 -> 224.83333 | AL6: 6.193 | AM6: =IF(AL6="","",AH6-AL6) -> 0.5195403 | AN6: =IF(AL6="","",ABS(AM6)) -> 0.5195403 | AO6: =IF(AL6="","",IFERROR(VLOOKUP(ROUND(AL6*2,0)/2,'Power curve'!$A$2:$D$53,4,FALSE()),0)) -> 1054 | AP6: =IF(AL6="","",AJ6-AO6) -> 295 | AQ6: =IF(AL6="","",ABS(AP6)) -> 295 | AR6: =IF(AL6="","",AO6*10/60) -> 175.66667 | AS6: =IF(AL6="","",AK6) -> 224.83333
A7: 46269.028 | B7: 7.502 | C7: 5.737 | D7: 7.693 | E7: 7.406 | F7: 8.36 | G7: 9.8 | H7: 9.4 | I7: =AVERAGE(B7:H7) -> 7.9854286 | J7: =MAX(0,'1 Relationship'!$O$4+'1 Relationship'!$O$3*I7) -> 6.7876867 | K7: =ROUND(J7*2,0)/2 -> 7 | L7: =IFERROR(VLOOKUP(K7,'Power curve'!$A$2:$B$53,2,FALSE()),0) -> 1691 | M7: =L7*10/60 -> 281.83333 | N7: 5.511 | O7: =IF(N7="","",J7-N7) -> 1.2766867 | P7: =IF(N7="","",ABS(O7)) -> 1.2766867 | Q7: =IF(N7="","",IFERROR(VLOOKUP(ROUND(N7*2,0)/2,'Power curve'!$A$2:$B$53,2,FALSE()),0)) -> 800 | R7: =IF(N7="","",L7-Q7) -> 891 | S7: =IF(N7="","",ABS(R7)) -> 891 | T7: =IF(N7="","",Q7*10/60) -> 133.33333 | U7: =IF(N7="","",M7) -> 281.83333 | V7: =MAX(0,'1 Relationship'!$P$4+'1 Relationship'!$P$3*I7) -> 7.3102034 | W7: =ROUND(V7*2,0)/2 -> 7.5 | X7: =IFERROR(VLOOKUP(W7,'Power curve'!$A$2:$C$53,3,FALSE()),0) -> 2083 | Y7: =X7*10/60 -> 347.16667 | Z7: 6.817 | AA7: =IF(Z7="","",V7-Z7) -> 0.49320336 | AB7: =IF(Z7="","",ABS(AA7)) -> 0.49320336 | AC7: =IF(Z7="","",IFERROR(VLOOKUP(ROUND(Z7*2,0)/2,'Power curve'!$A$2:$C$53,3,FALSE()),0)) -> 1691 | AD7: =IF(Z7="","",X7-AC7) -> 392 | AE7: =IF(Z7="","",ABS(AD7)) -> 392 | AF7: =IF(Z7="","",AC7*10/60) -> 281.83333 | AG7: =IF(Z7="","",Y7) -> 347.16667 | AH7: =MAX(0,'1 Relationship'!$Q$4+'1 Relationship'!$Q$3*I7) -> 6.7724275 | AI7: =ROUND(AH7*2,0)/2 -> 7 | AJ7: =IFERROR(VLOOKUP(AI7,'Power curve'!$A$2:$D$53,4,FALSE()),0) -> 1691 | AK7: =AJ7*10/60 -> 281.83333 | AL7: 6.072 | AM7: =IF(AL7="","",AH7-AL7) -> 0.70042748 | AN7: =IF(AL7="","",ABS(AM7)) -> 0.70042748 | AO7: =IF(AL7="","",IFERROR(VLOOKUP(ROUND(AL7*2,0)/2,'Power curve'!$A$2:$D$53,4,FALSE()),0)) -> 1054 | AP7: =IF(AL7="","",AJ7-AO7) -> 637 | AQ7: =IF(AL7="","",ABS(AP7)) -> 637 | AR7: =IF(AL7="","",AO7*10/60) -> 175.66667 | AS7: =IF(AL7="","",AK7) -> 281.83333
A8: 46269.035 | B8: 7.356 | C8: 7.156 | D8: 7.615 | E8: 7.36 | F8: 8.065 | G8: 9.4 | H8: 9.1 | I8: =AVERAGE(B8:H8) -> 8.0074286 | J8: =MAX(0,'1 Relationship'!$O$4+'1 Relationship'!$O$3*I8) -> 6.8037537 | K8: =ROUND(J8*2,0)/2 -> 7 | L8: =IFERROR(VLOOKUP(K8,'Power curve'!$A$2:$B$53,2,FALSE()),0) -> 1691 | M8: =L8*10/60 -> 281.83333 | N8: 5.7 | O8: =IF(N8="","",J8-N8) -> 1.1037537 | P8: =IF(N8="","",ABS(O8)) -> 1.1037537 | Q8: =IF(N8="","",IFERROR(VLOOKUP(ROUND(N8*2,0)/2,'Power curve'!$A$2:$B$53,2,FALSE()),0)) -> 800 | R8: =IF(N8="","",L8-Q8) -> 891 | S8: =IF(N8="","",ABS(R8)) -> 891 | T8: =IF(N8="","",Q8*10/60) -> 133.33333 | U8: =IF(N8="","",M8) -> 281.83333 | V8: =MAX(0,'1 Relationship'!$P$4+'1 Relationship'!$P$3*I8) -> 7.3287317 | W8: =ROUND(V8*2,0)/2 -> 7.5 | X8: =IFERROR(VLOOKUP(W8,'Power curve'!$A$2:$C$53,3,FALSE()),0) -> 2083 | Y8: =X8*10/60 -> 347.16667 | Z8: 6.655 | AA8: =IF(Z8="","",V8-Z8) -> 0.67373165 | AB8: =IF(Z8="","",ABS(AA8)) -> 0.67373165 | AC8: =IF(Z8="","",IFERROR(VLOOKUP(ROUND(Z8*2,0)/2,'Power curve'!$A$2:$C$53,3,FALSE()),0)) -> 1349 | AD8: =IF(Z8="","",X8-AC8) -> 734 | AE8: =IF(Z8="","",ABS(AD8)) -> 734 | AF8: =IF(Z8="","",AC8*10/60) -> 224.83333 | AG8: =IF(Z8="","",Y8) -> 347.16667 | AH8: =MAX(0,'1 Relationship'!$Q$4+'1 Relationship'!$Q$3*I8) -> 6.7888379 | AI8: =ROUND(AH8*2,0)/2 -> 7 | AJ8: =IFERROR(VLOOKUP(AI8,'Power curve'!$A$2:$D$53,4,FALSE()),0) -> 1691 | AK8: =AJ8*10/60 -> 281.83333 | AL8: 4.831 | AM8: =IF(AL8="","",AH8-AL8) -> 1.9578379 | AN8: =IF(AL8="","",ABS(AM8)) -> 1.9578379 | AO8: =IF(AL8="","",IFERROR(VLOOKUP(ROUND(AL8*2,0)/2,'Power curve'!$A$2:$D$53,4,FALSE()),0)) -> 584 | AP8: =IF(AL8="","",AJ8-AO8) -> 1107 | AQ8: =IF(AL8="","",ABS(AP8)) -> 1107 | AR8: =IF(AL8="","",AO8*10/60) -> 97.333333 | AS8: =IF(AL8="","",AK8) -> 281.83333
A9: 46269.042 | B9: 7.489 | C9: 7.219 | D9: 7.656 | E9: 7.251 | F9: 7.655 | G9: 9.1 | H9: 8.6 | I9: =AVERAGE(B9:H9) -> 7.8528571 | J9: =MAX(0,'1 Relationship'!$O$4+'1 Relationship'!$O$3*I9) -> 6.6908672 | K9: =ROUND(J9*2,0)/2 -> 6.5 | L9: =IFERROR(VLOOKUP(K9,'Power curve'!$A$2:$B$53,2,FALSE()),0) -> 1349 | M9: =L9*10/60 -> 224.83333 | N9: 5.886 | O9: =IF(N9="","",J9-N9) -> 0.80486718 | P9: =IF(N9="","",ABS(O9)) -> 0.80486718 | Q9: =IF(N9="","",IFERROR(VLOOKUP(ROUND(N9*2,0)/2,'Power curve'!$A$2:$B$53,2,FALSE()),0)) -> 1054 | R9: =IF(N9="","",L9-Q9) -> 295 | S9: =IF(N9="","",ABS(R9)) -> 295 | T9: =IF(N9="","",Q9*10/60) -> 175.66667 | U9: =IF(N9="","",M9) -> 224.83333 | V9: =MAX(0,'1 Relationship'!$P$4+'1 Relationship'!$P$3*I9) -> 7.1985524 | W9: =ROUND(V9*2,0)/2 -> 7 | X9: =IFERROR(VLOOKUP(W9,'Power curve'!$A$2:$C$53,3,FALSE()),0) -> 1691 | Y9: =X9*10/60 -> 281.83333 | Z9: 7.088 | AA9: =IF(Z9="","",V9-Z9) -> 0.11055235 | AB9: =IF(Z9="","",ABS(AA9)) -> 0.11055235 | AC9: =IF(Z9="","",IFERROR(VLOOKUP(ROUND(Z9*2,0)/2,'Power curve'!$A$2:$C$53,3,FALSE()),0)) -> 1691 | AD9: =IF(Z9="","",X9-AC9) -> 0 | AE9: =IF(Z9="","",ABS(AD9)) -> 0 | AF9: =IF(Z9="","",AC9*10/60) -> 281.83333 | AG9: =IF(Z9="","",Y9) -> 281.83333 | AH9: =MAX(0,'1 Relationship'!$Q$4+'1 Relationship'!$Q$3*I9) -> 6.673539 | AI9: =ROUND(AH9*2,0)/2 -> 6.5 | AJ9: =IFERROR(VLOOKUP(AI9,'Power curve'!$A$2:$D$53,4,FALSE()),0) -> 1349 | AK9: =AJ9*10/60 -> 224.83333 | AL9: 5.611 | AM9: =IF(AL9="","",AH9-AL9) -> 1.062539 | AN9: =IF(AL9="","",ABS(AM9)) -> 1.062539 | AO9: =IF(AL9="","",IFERROR(VLOOKUP(ROUND(AL9*2,0)/2,'Power curve'!$A$2:$D$53,4,FALSE()),0)) -> 800 | AP9: =IF(AL9="","",AJ9-AO9) -> 549 | AQ9: =IF(AL9="","",ABS(AP9)) -> 549 | AR9: =IF(AL9="","",AO9*10/60) -> 133.33333 | AS9: =IF(AL9="","",AK9) -> 224.83333
A10: 46269.049 | B10: 7.112 | C10: 6.984 | D10: 7.136 | E10: 6.714 | F10: 7.414 | G10: 8.7 | H10: 8.5 | I10: =AVERAGE(B10:H10) -> 7.5085714 | J10: =MAX(0,'1 Relationship'!$O$4+'1 Relationship'!$O$3*I10) -> 6.4394286 | K10: =ROUND(J10*2,0)/2 -> 6.5 | L10: =IFERROR(VLOOKUP(K10,'Power curve'!$A$2:$B$53,2,FALSE()),0) -> 1349 | M10: =L10*10/60 -> 224.83333 | N10: 5.922 | O10: =IF(N10="","",J10-N10) -> 0.51742856 | P10: =IF(N10="","",ABS(O10)) -> 0.51742856 | Q10: =IF(N10="","",IFERROR(VLOOKUP(ROUND(N10*2,0)/2,'Power curve'!$A$2:$B$53,2,FALSE()),0)) -> 1054 | R10: =IF(N10="","",L10-Q10) -> 295 | S10: =IF(N10="","",ABS(R10)) -> 295 | T10: =IF(N10="","",Q10*10/60) -> 175.66667 | U10: =IF(N10="","",M10) -> 224.83333 | V10: =MAX(0,'1 Relationship'!$P$4+'1 Relationship'!$P$3*I10) -> 6.9085966 | W10: =ROUND(V10*2,0)/2 -> 7 | X10: =IFERROR(VLOOKUP(W10,'Power curve'!$A$2:$C$53,3,FALSE()),0) -> 1691 | Y10: =X10*10/60 -> 281.83333 | Z10: 7.228 | AA10: =IF(Z10="","",V10-Z10) -> -0.31940339 | AB10: =IF(Z10="","",ABS(AA10)) -> 0.31940339 | AC10: =IF(Z10="","",IFERROR(VLOOKUP(ROUND(Z10*2,0)/2,'Power curve'!$A$2:$C$53,3,FALSE()),0)) -> 1691 | AD10: =IF(Z10="","",X10-AC10) -> 0 | AE10: =IF(Z10="","",ABS(AD10)) -> 0 | AF10: =IF(Z10="","",AC10*10/60) -> 281.83333 | AG10: =IF(Z10="","",Y10) -> 281.83333 | AH10: =MAX(0,'1 Relationship'!$Q$4+'1 Relationship'!$Q$3*I10) -> 6.4167274 | AI10: =ROUND(AH10*2,0)/2 -> 6.5 | AJ10: =IFERROR(VLOOKUP(AI10,'Power curve'!$A$2:$D$53,4,FALSE()),0) -> 1349 | AK10: =AJ10*10/60 -> 224.83333 | AL10: 5.673 | AM10: =IF(AL10="","",AH10-AL10) -> 0.74372744 | AN10: =IF(AL10="","",ABS(AM10)) -> 0.74372744 | AO10: =IF(AL10="","",IFERROR(VLOOKUP(ROUND(AL10*2,0)/2,'Power curve'!$A$2:$D$53,4,FALSE()),0)) -> 800 | AP10: =IF(AL10="","",AJ10-AO10) -> 549 | AQ10: =IF(AL10="","",ABS(AP10)) -> 549 | AR10: =IF(AL10="","",AO10*10/60) -> 133.33333 | AS10: =IF(AL10="","",AK10) -> 224.83333
A11: 46269.056 | B11: 7.354 | C11: 6.961 | D11: 7.359 | E11: 7.208 | F11: 7.498 | G11: 8.8 | H11: 9.2 | I11: =AVERAGE(B11:H11) -> 7.7685714 | J11: =MAX(0,'1 Relationship'!$O$4+'1 Relationship'!$O$3*I11) -> 6.6293117 | K11: =ROUND(J11*2,0)/2 -> 6.5 | L11: =IFERROR(VLOOKUP(K11,'Power curve'!$A$2:$B$53,2,FALSE()),0) -> 1349 | M11: =L11*10/60 -> 224.83333 | N11: 6.594 | O11: =IF(N11="","",J11-N11) -> 0.035311669 | P11: =IF(N11="","",ABS(O11)) -> 0.035311669 | Q11: =IF(N11="","",IFERROR(VLOOKUP(ROUND(N11*2,0)/2,'Power curve'!$A$2:$B$53,2,FALSE()),0)) -> 1349 | R11: =IF(N11="","",L11-Q11) -> 0 | S11: =IF(N11="","",ABS(R11)) -> 0 | T11: =IF(N11="","",Q11*10/60) -> 224.83333 | U11: =IF(N11="","",M11) -> 224.83333 | V11: =MAX(0,'1 Relationship'!$P$4+'1 Relationship'!$P$3*I11) -> 7.1275673 | W11: =ROUND(V11*2,0)/2 -> 7 | X11: =IFERROR(VLOOKUP(W11,'Power curve'!$A$2:$C$53,3,FALSE()),0) -> 1691 | Y11: =X11*10/60 -> 281.83333 | Z11: 6.881 | AA11: =IF(Z11="","",V11-Z11) -> 0.24656733 | AB11: =IF(Z11="","",ABS(AA11)) -> 0.24656733 | AC11: =IF(Z11="","",IFERROR(VLOOKUP(ROUND(Z11*2,0)/2,'Power curve'!$A$2:$C$53,3,FALSE()),0)) -> 1691 | AD11: =IF(Z11="","",X11-AC11) -> 0 | AE11: =IF(Z11="","",ABS(AD11)) -> 0 | AF11: =IF(Z11="","",AC11*10/60) -> 281.83333 | AG11: =IF(Z11="","",Y11) -> 281.83333 | AH11: =MAX(0,'1 Relationship'!$Q$4+'1 Relationship'!$Q$3*I11) -> 6.6106681 | AI11: =ROUND(AH11*2,0)/2 -> 6.5 | AJ11: =IFERROR(VLOOKUP(AI11,'Power curve'!$A$2:$D$53,4,FALSE()),0) -> 1349 | AK11: =AJ11*10/60 -> 224.83333 | AL11: 6.12 | AM11: =IF(AL11="","",AH11-AL11) -> 0.49066815 | AN11: =IF(AL11="","",ABS(AM11)) -> 0.49066815 | AO11: =IF(AL11="","",IFERROR(VLOOKUP(ROUND(AL11*2,0)/2,'Power curve'!$A$2:$D$53,4,FALSE()),0)) -> 1054 | AP11: =IF(AL11="","",AJ11-AO11) -> 295 | AQ11: =IF(AL11="","",ABS(AP11)) -> 295 | AR11: =IF(AL11="","",AO11*10/60) -> 175.66667 | AS11: =IF(AL11="","",AK11) -> 224.83333
A12: 46269.062 | B12: 7.137 | C12: 6.587 | D12: 6.941 | E12: 6.553 | F12: 7.68 | G12: 9.3 | H12: 9.2 | I12: =AVERAGE(B12:H12) -> 7.6282857 | J12: =MAX(0,'1 Relationship'!$O$4+'1 Relationship'!$O$3*I12) -> 6.5268583 | K12: =ROUND(J12*2,0)/2 -> 6.5 | L12: =IFERROR(VLOOKUP(K12,'Power curve'!$A$2:$B$53,2,FALSE()),0) -> 1349 | M12: =L12*10/60 -> 224.83333 | N12: 6.138 | O12: =IF(N12="","",J12-N12) -> 0.38885825 | P12: =IF(N12="","",ABS(O12)) -> 0.38885825 | Q12: =IF(N12="","",IFERROR(VLOOKUP(ROUND(N12*2,0)/2,'Power curve'!$A$2:$B$53,2,FALSE()),0)) -> 1054 | R12: =IF(N12="","",L12-Q12) -> 295 | S12: =IF(N12="","",ABS(R12)) -> 295 | T12: =IF(N12="","",Q12*10/60) -> 175.66667 | U12: =IF(N12="","",M12) -> 224.83333 | V12: =MAX(0,'1 Relationship'!$P$4+'1 Relationship'!$P$3*I12) -> 7.0094194 | W12: =ROUND(V12*2,0)/2 -> 7 | X12: =IFERROR(VLOOKUP(W12,'Power curve'!$A$2:$C$53,3,FALSE()),0) -> 1691 | Y12: =X12*10/60 -> 281.83333 | Z12: 7.069 | AA12: =IF(Z12="","",V12-Z12) -> -0.059580609 | AB12: =IF(Z12="","",ABS(AA12)) -> 0.059580609 | AC12: =IF(Z12="","",IFERROR(VLOOKUP(ROUND(Z12*2,0)/2,'Power curve'!$A$2:$C$53,3,FALSE()),0)) -> 1691 | AD12: =IF(Z12="","",X12-AC12) -> 0 | AE12: =IF(Z12="","",ABS(AD12)) -> 0 | AF12: =IF(Z12="","",AC12*10/60) -> 281.83333 | AG12: =IF(Z12="","",Y12) -> 281.83333 | AH12: =MAX(0,'1 Relationship'!$Q$4+'1 Relationship'!$Q$3*I12) -> 6.5060254 | AI12: =ROUND(AH12*2,0)/2 -> 6.5 | AJ12: =IFERROR(VLOOKUP(AI12,'Power curve'!$A$2:$D$53,4,FALSE()),0) -> 1349 | AK12: =AJ12*10/60 -> 224.83333 | AL12: 6.516 | AM12: =IF(AL12="","",AH12-AL12) -> -0.0099745851 | AN12: =IF(AL12="","",ABS(AM12)) -> 0.0099745851 | AO12: =IF(AL12="","",IFERROR(VLOOKUP(ROUND(AL12*2,0)/2,'Power curve'!$A$2:$D$53,4,FALSE()),0)) -> 1349 | AP12: =IF(AL12="","",AJ12-AO12) -> 0 | AQ12: =IF(AL12="","",ABS(AP12)) -> 0 | AR12: =IF(AL12="","",AO12*10/60) -> 224.83333 | AS12: =IF(AL12="","",AK12) -> 224.83333
A13: 46269.069 | B13: 7.778 | C13: 7.201 | D13: 7.833 | E13: 7.067 | F13: 8.508 | G13: 8.8 | H13: 8.4 | I13: =AVERAGE(B13:H13) -> 7.941 | J13: =MAX(0,'1 Relationship'!$O$4+'1 Relationship'!$O$3*I13) -> 6.7552396 | K13: =ROUND(J13*2,0)/2 -> 7 | L13: =IFERROR(VLOOKUP(K13,'Power curve'!$A$2:$B$53,2,FALSE()),0) -> 1691 | M13: =L13*10/60 -> 281.83333 | N13: 7.011 | O13: =IF(N13="","",J13-N13) -> -0.25576035 | P13: =IF(N13="","",ABS(O13)) -> 0.25576035 | Q13: =IF(N13="","",IFERROR(VLOOKUP(ROUND(N13*2,0)/2,'Power curve'!$A$2:$B$53,2,FALSE()),0)) -> 1691 | R13: =IF(N13="","",L13-Q13) -> 0 | S13: =IF(N13="","",ABS(R13)) -> 0 | T13: =IF(N13="","",Q13*10/60) -> 281.83333 | U13: =IF(N13="","",M13) -> 281.83333 | V13: =MAX(0,'1 Relationship'!$P$4+'1 Relationship'!$P$3*I13) -> 7.2727858 | W13: =ROUND(V13*2,0)/2 -> 7.5 | X13: =IFERROR(VLOOKUP(W13,'Power curve'!$A$2:$C$53,3,FALSE()),0) -> 2083 | Y13: =X13*10/60 -> 347.16667 | Z13: 7.505 | AA13: =IF(Z13="","",V13-Z13) -> -0.23221417 | AB13: =IF(Z13="","",ABS(AA13)) -> 0.23221417 | AC13: =IF(Z13="","",IFERROR(VLOOKUP(ROUND(Z13*2,0)/2,'Power curve'!$A$2:$C$53,3,FALSE()),0)) -> 2083 | AD13: =IF(Z13="","",X13-AC13) -> 0 | AE13: =IF(Z13="","",ABS(AD13)) -> 0 | AF13: =IF(Z13="","",AC13*10/60) -> 347.16667 | AG13: =IF(Z13="","",Y13) -> 347.16667 | AH13: =MAX(0,'1 Relationship'!$Q$4+'1 Relationship'!$Q$3*I13) -> 6.7392871 | AI13: =ROUND(AH13*2,0)/2 -> 6.5 | AJ13: =IFERROR(VLOOKUP(AI13,'Power curve'!$A$2:$D$53,4,FALSE()),0) -> 1349 | AK13: =AJ13*10/60 -> 224.83333 | AL13: 5.925 | AM13: =IF(AL13="","",AH13-AL13) -> 0.81428707 | AN13: =IF(AL13="","",ABS(AM13)) -> 0.81428707 | AO13: =IF(AL13="","",IFERROR(VLOOKUP(ROUND(AL13*2,0)/2,'Power curve'!$A$2:$D$53,4,FALSE()),0)) -> 1054 | AP13: =IF(AL13="","",AJ13-AO13) -> 295 | AQ13: =IF(AL13="","",ABS(AP13)) -> 295 | AR13: =IF(AL13="","",AO13*10/60) -> 175.66667 | AS13: =IF(AL13="","",AK13) -> 224.83333
